@Test public void resumeWithError(){
  Completable.error(new TestException()).onErrorResumeNext(Functions.justFunction(Completable.error(new TestException("second")))).test().assertFailureAndMessage(TestException.class,"second");
}
