/** 
 * Test ensuring that if a snapshot call happens right after an async exception is caught, it should be rethrown.
 */
@SuppressWarnings("ResultOfMethodCallIgnored") @Test public void testAsyncErrorRethrownOnCheckpoint() throws Throwable {
  final DummyFlinkKinesisProducer<String> producer=new DummyFlinkKinesisProducer<>(new SimpleStringSchema());
  OneInputStreamOperatorTestHarness<String,Object> testHarness=new OneInputStreamOperatorTestHarness<>(new StreamSink<>(producer));
  testHarness.open();
  testHarness.processElement(new StreamRecord<>("msg-1"));
  producer.getPendingRecordFutures().get(0).setException(new Exception("artificial async exception"));
  try {
    testHarness.snapshot(123L,123L);
  }
 catch (  Exception e) {
    Assert.assertTrue(ExceptionUtils.findThrowableWithMessage(e,"artificial async exception").isPresent());
    return;
  }
  Assert.fail();
}
